Workbook

Sheet Indicaciones
D1: Examen 2 | G1: Finanzas Empresariales
G2: 2025-2
B4: Indicaciones: | C4: - Duración: 50 minutos.
C5: - Al terminar, carga tu archivo de Excel en Canvas. Debes mostrar las fórmulas empleadas, no solo los valores.
C6: - La respuesta debe indicarla en la celda resaltada en amarrillo, haciendo referencia a la celda en la que ha hecho sus cálculos.
C7: - No agregue ningún valor en la celdas en color verde.
C8: - El desarrollo de la prueba debe ser de manera individual.y no se permite materiales de apoyo.
C9: - De identificarse trabajos copiados, parcial o totalmente, se procederá y sancionará según reglamento.
B11: Calificación: | C11: Hoja | D11: Tema | E11: Puntaje por pregunta | F11: Puntaje del alumno
C12: Parte 1 | D12: ='Parte 1'!B1 -> Preguntas de teoría | E12: 5 | F12: ='Parte 1'!A1 -> 0
C13: Parte 2 | D13: ='Parte 2'!B1 -> Estado de flujo de efectivo | E13: 4 | F13: ='Parte 2'!A1 -> 0
C14: Parte 3 | D14: ='Parte 3'!B1 -> Ratios | E14: 4 | F14: ='Parte 3'!A1 -> 0
C15: Parte 2 | D15: ='Parte 4'!B1 -> Tendencias | E15: 2 | F15: ='Parte 4'!A1 -> 0
C16: Parte 3 | D16: ='Parte 5'!B1 -> Tasas de interés | E16: 5 | F16: ='Parte 5'!A1 -> 0
E18: =IF(SUM(E12:E16)=20,"Nota",IF(SUM(E12:E16)>20,"Excede en "&SUM(E12:E16)-20,"Falta "&20-SUM(E12:E16))) -> Nota | F18: =ROUND(SUM(F12:F16),0) -> 0

Sheet Parte 1
A1: =IF(Indicaciones!G18="","",SUM(A4:A13)) -> 0 | B1: Preguntas de teoría
B4: Las preguntas de teoría las encontrarán en Canvas

Sheet Parte 2
A1: =SUM(A17:A27) -> 0 | B1: Estado de flujo de efectivo
B3: Datos
B4: Utilidad Neta | F4: 120000
B5: Depreciación | F5: 25000
B6: Amortización | F6: 5000
B7: Aumento en cuentas por cobrar | F7: 15000
B8: Disminución en Inventarios | F8: 8000
B9: Aumento en cuentas por pagar | F9: 12000
B10: Disminución en sueldos por pagar | F10: 4000
B11: Compra de nuevo local comercial | F11: 180000
B12: Compra de equipos de computo | F12: 25000
B13: Préstamo bancario a largo plazo recibido | F13: 150000
B14: Pago de dividendos a accionistas | F14: 40000
B15: Cancelación de deuda | F15: 30000
B17: 1 | C17: 0.5 | D17: Elabore el flujo neto operativo. | I17: 1-
C18: 0.5 | D18: Interprete el resultado. | I18: =F4+F5+F6-F7+F8+F9-F10 -> 151000
I19: Interpretación:
B20: 2 | C20: 0.5 | D20: Elabore el flujo neto de inversión. | I20: La empresa generó S/ 151,000 de efectivo a partir de sus operaciones principales (ventas y costos), lo cual es positivo e indica que el negocio es rentable en términos de efectivo.
C21: 0.5 | D21: Interprete el resultado.
I22: 2-
B23: 3 | C23: 0.5 | D23: Elabore el flujo neto de financiamiento. | I23: =-F11-F12 -> -205000
C24: 0.5 | D24: Interprete el resultado. | I24: Interpretación:
I25: El flujo es negativo (S/ -205,000), lo que indica que la empresa está invirtiendo fuertemente en activos a largo plazo (expansión/renovación de local y equipos). Esta es una señal de crecimiento.
B26: 4 | C26: 0.5 | D26: Elabore el Estado de flujo de efectivo.
C27: 0.5 | D27: Interprete el resultado.
I28: 3-
I29: =F13-F14-F15 -> 80000
I30: Interpretación:
I31: El flujo es positivo (S/ 80,000). La empresa recibió más efectivo del que pagó en financiamiento, principalmente por la obtención de un préstamo a largo plazo (S/ 150,000).
I33: 4-
I34: =I18+I23+I29 -> 26000
I35: Interpretación:
I36: El flujo de efectivo del periodo fue positivo en S/ 26,000. Esto significa que, después de financiar sus operaciones, hacer grandes inversiones en activos fijos y gestionar su deuda/capital, la empresa logró un aumento neto en su saldo de efectivo (Caja y Bancos) de S/ 26,000 al final del periodo.

Sheet Parte 3
A1: =IF(Indicaciones!G18="","",SUM(A23:A30)) -> 0 | B1: Ratios
C3: TechSol S.A. | I3: TechSol S.A.
C4: Estado de Resultados | I4: Estado de Situación Financiera
C5: Del 01/enero a 31/diciembre de … | I5: Al 31 de diciembre de …
C6: En Soles | I6: En Soles
E7: 2022 | F7: 2023 | G7: 2024 | I7: ACTIVO | J7: 2022 | K7: 2023 | L7: 2024
C8: Ingresos por Ventas | E8: 400000 | F8: 450000 | G8: 520000 | I8: ACTIVO CORRIENTE
C9: (-) Costo de Ventas | E9: -240000 | F9: -270000 | G9: -320000 | I9: Caja y bancos | J9: 20000 | K9: 25000 | L9: 30000
C10: Utilidad bruta | E10: =SUM(E8:E9) -> 160000 | F10: =SUM(F8:F9) -> 180000 | G10: =SUM(G8:G9) -> 200000 | I10: Cuentas por cobrar comerciales | J10: 35000 | K10: 45000 | L10: 60000
C11: (-) Gastos operativos | E11: -65000 | F11: -75000 | G11: -85000 | I11: Inventarios | J11: 70000 | K11: 80000 | L11: 95000
C12: Utilidad operativa | E12: =SUM(E10:E11) -> 95000 | F12: =SUM(F10:F11) -> 105000 | G12: =SUM(G10:G11) -> 115000 | I12: Total Activo Corriente | J12: =SUM(J9:J11) -> 125000 | K12: =SUM(K9:K11) -> 150000 | L12: =SUM(L9:L11) -> 185000
C13: (+) Ingresos financieros | E13: 1000 | F13: 0 | G13: 0 | I13: ACTIVO NO CORRIENTE
C14: (-) Gastos financieros | E14: -12000 | F14: -15000 | G14: -18000 | I14: Propiedad, Planta y Equipo | J14: 180000 | K14: 200000 | L14: 230000
C15: Utilidad antes de impuestos | E15: =SUM(E12:E14) -> 84000 | F15: =SUM(F12:F14) -> 90000 | G15: =SUM(G12:G14) -> 97000 | I15: (-) Depreciación Acumulada | J15: -30000 | K15: -40000 | L15: -55000
C16: (-) Impuesto a la Renta (29.5%) | E16: =-E15*29.5% -> -24780 | F16: =-F15*29.5% -> -26550 | G16: =-G15*29.5% -> -28615 | I16: Total Activo No Corriente | J16: =SUM(J14:J15) -> 150000 | K16: =SUM(K14:K15) -> 160000 | L16: =SUM(L14:L15) -> 175000
C17: Utilidad neta | E17: =SUM(E15:E16) -> 59220 | F17: =SUM(F15:F16) -> 63450 | G17: =SUM(G15:G16) -> 68385 | I17: TOTAL ACTIVO | J17: =SUM(J16,J12) -> 275000 | K17: =SUM(K16,K12) -> 310000 | L17: =SUM(L16,L12) -> 360000
I18: PASIVO CORRIENTE
I19: Cuentas por Pagar Comerciales | J19: 35000 | K19: 40000 | L19: 55000
B20: En las siguientes preguntas utilice los ratios que crea conveniente: | I20: Sobregiro Bancario | J20: 15000 | K20: 20000 | L20: 25000
I21: Total Pasivo Corriente | J21: =SUM(J19:J20) -> 50000 | K21: =SUM(K19:K20) -> 60000 | L21: =SUM(L19:L20) -> 80000
B22: 1 | C22: Mida la capacidad de la empresa para pagar sus obligaciones a CP. | I22: PASIVO NO CORRIENTE
C23: 0.25 | D23: Nombre de ratio | E23: Ratio Corriente | I23: Préstamos Bancarios L/P | J23: 90000 | K23: 100000 | L23: 110000
C24: 0.25 | D24: Cálculo del ratio | E24: =L12/L21 -> 2.3125 | I24: Total Pasivo No Corriente | J24: =J23 -> 90000 | K24: =K23 -> 100000 | L24: =L23 -> 110000
C25: 1.5 | D25: Interpretación | E25: Por cada Sol de deuda de corto plazo (Pasivo Corriente), la empresa cuenta con S/ 2.31 de Activo Corriente para respaldarla. Este es un nivel de liquidez saludable y superior al mínimo aceptable (generalmente 1.0). | I25: TOTAL PASIVO | J25: =SUM(J24,J21) -> 140000 | K25: =SUM(K24,K21) -> 160000 | L25: =SUM(L24,L21) -> 190000
I26: PATRIMONIO
B27: 2 | C27: Mida la generación de utilidades de la empresa versus sus ventas o inversión. | I27: Capital Social | J27: 110000 | K27: 120000 | L27: 130000
C28: 0.25 | D28: Nombre de ratio | E28: Margen Neto | I28: Resultados Acumulados | J28: =E17 -> 59220 | K28: =F17 -> 63450 | L28: =G17 -> 68385
C29: 0.25 | D29: Cálculo del ratio | E29: =G17/G8 -> 0.13150962 | I29: Dividendos | J29: -75780 | K29: -86550 | L29: -101615
C30: 1.5 | D30: Interpretación | E30: Por cada Sol de venta, la empresa genera S/ 0.1315 (o 13.15%) de Utilidad Neta después de cubrir todos sus costos, gastos e impuestos. Este ratio mide la rentabilidad final del negocio | I30: Total Patrimonio | J30: 135000 | K30: 150000 | L30: 170000
I31: TOTAL PASIVO Y PATRIMONIO | J31: 275000 | K31: 310000 | L31: 360000
B33: Estas perguntas serían alternativas para modificar el original
C34: Evalúe la eficiencia de la empresa en la gestión de sus recursos.
C35: 0.25 | D35: Nombre de ratio
C36: 0.25 | D36: Cálculo del ratio
C37: 1.5 | D37: Interpretación
C39: Mida la capacidad de la empresa para pagos de LP y estructura de capital.
C40: 0.25 | D40: Nombre de ratio
C41: 0.25 | D41: Cálculo del ratio
C42: 1.5 | D42: Interpretación

Sheet Parte 4
A1: =IF(Indicaciones!G18="","",SUM(A22:A29)) -> 0 | B1: Tendencias
C3: TechSol S.A. | J3: TechSol S.A.
C4: Estado de Resultados | J4: Estado de Situación Financiera
C5: Del 01/enero a 31/diciembre de … | J5: Al 31 de diciembre de …
C6: En Soles | J6: En Soles
E7: 2022 | F7: 2023 | G7: 2024 | J7: ACTIVO | K7: 2022 | L7: 2023 | M7: 2024
C8: Ingresos por Ventas | E8: 400000 | F8: 450000 | G8: 520000 | J8: ACTIVO CORRIENTE
C9: Costo de Ventas | E9: -240000 | F9: -270000 | G9: -320000 | J9: Caja y bancos | K9: 20000 | L9: 25000 | M9: 30000
C10: Utilidad bruta | E10: =SUM(E8:E9) -> 160000 | F10: =SUM(F8:F9) -> 180000 | G10: =SUM(G8:G9) -> 200000 | J10: Cuentas por cobrar comerciales | K10: 35000 | L10: 45000 | M10: 60000
C11: Gastos operativos | E11: -65000 | F11: -75000 | G11: -85000 | J11: Inventarios | K11: 70000 | L11: 80000 | M11: 95000
C12: Utilidad operativa | E12: =SUM(E10:E11) -> 95000 | F12: =SUM(F10:F11) -> 105000 | G12: =SUM(G10:G11) -> 115000 | J12: Total Activo Corriente | K12: =SUM(K9:K11) -> 125000 | L12: =SUM(L9:L11) -> 150000 | M12: =SUM(M9:M11) -> 185000
C13: Ingresos financieros | E13: 1000 | J13: ACTIVO NO CORRIENTE
C14: Gastos financieros | E14: -12000 | F14: -15000 | G14: -18000 | J14: Propiedad, Planta y Equipo | K14: 180000 | L14: 200000 | M14: 230000
C15: Utilidad antes de impuestos | E15: =SUM(E12:E14) -> 84000 | F15: =SUM(F12:F14) -> 90000 | G15: =SUM(G12:G14) -> 97000 | J15: (-) Depreciación Acumulada | K15: -30000 | L15: -40000 | M15: -55000
C16: Impuesto a la Renta (29.5%) | E16: =-E15*29.5% -> -24780 | F16: =-F15*29.5% -> -26550 | G16: =-G15*29.5% -> -28615 | J16: Total Activo No Corriente | K16: =SUM(K14:K15) -> 150000 | L16: =SUM(L14:L15) -> 160000 | M16: =SUM(M14:M15) -> 175000
C17: Utilidad neta | E17: =SUM(E15:E16) -> 59220 | F17: =SUM(F15:F16) -> 63450 | G17: =SUM(G15:G16) -> 68385 | J17: TOTAL ACTIVO | K17: =SUM(K16,K12) -> 275000 | L17: =SUM(L16,L12) -> 310000 | M17: =SUM(M16,M12) -> 360000
J18: PASIVO CORRIENTE
J19: Cuentas por Pagar Comerciales | K19: 35000 | L19: 40000 | M19: 55000
J20: Sobregiro Bancario | K20: 15000 | L20: 20000 | M20: 25000
B21: 1 | C21: En el Estado de Resultados del año 2024: | J21: Total Pasivo Corriente | K21: =SUM(K19:K20) -> 50000 | L21: =SUM(L19:L20) -> 60000 | M21: =SUM(M19:M20) -> 80000
C22: 0.25 | D22: Calcule la participación porcentual de cada partida. | J22: PASIVO NO CORRIENTE
C23: 0.25 | D23: Nombre del costo o gasto que tiene mayor peso. | J23: Préstamos Bancarios L/P | K23: 90000 | L23: 100000 | M23: 110000
C24: 0.5 | D24: Interprete el resultado anterior. | J24: Total Pasivo No Corriente | K24: =K23 -> 90000 | L24: =L23 -> 100000 | M24: =M23 -> 110000
J25: TOTAL PASIVO | K25: =SUM(K24,K21) -> 140000 | L25: =SUM(L24,L21) -> 160000 | M25: =SUM(M24,M21) -> 190000
B26: 2 | C26: En el Estado de Situación Financiera: | J26: PATRIMONIO
C27: 0.25 | D27: Calcule el crecimiento de cada partida respecto al año 2022. | J27: Capital Social | K27: 110000 | L27: 120000 | M27: 130000
C28: 0.25 | D28: Nombre del ítem que creció menos el 2024. | J28: Resultados Acumulados | K28: =E17 -> 59220 | L28: =F17 -> 63450 | M28: =G17 -> 68385
C29: 0.5 | D29: Interprete el resultado anterior. | J29: Dividendos | K29: -75780 | L29: -86550 | M29: -101615
J30: Total Patrimonio | K30: 135000 | L30: 150000 | M30: 170000
C31: 1- | J31: TOTAL PASIVO Y PATRIMONIO | K31: 275000 | L31: 310000 | M31: 360000
C32: Ingresos por ventas | E32: =G8/$G$8 -> 1 | G32: El costo o gasto que tiene mayor peso es el Costo de Ventas con 61.54% de los Ingresos por Ventas.
C33: Costo de ventas | E33: =-G9/$G$8 -> 0.61538462
C34: Gastos operativos | E34: =-G11/$G$8 -> 0.16346154 | G34: Interpretación: El 61.54% de cada sol que ingresa por ventas se destina a cubrir el Costo de los bienes o servicios vendidos. Es el rubro más significativo en la estructura de costos y gastos, por lo que cualquier variación en este costo tendrá el mayor impacto en la rentabilidad de la empresa.
C35: Gastos financieros | E35: =-G14/$G$8 -> 0.034615385
C36: Impuesto a la renta | E36: =-G16/$G$8 -> 0.055028846
C38: 2-
C40: Caja y bancos | E40: =(M9-K9)/K9 -> 0.5 | G40: El ítem que creció menos en el 2024 respecto al 2022 es el Capital Social con un crecimiento del 18.18%.
C41: Cuentas por Cobrar | E41: =(M10-K10)/K10 -> 0.71428571
C42: Inventarios | E42: =(M11-K11)/K11 -> 0.35714286 | G42: Interpretación: El Capital Social es el rubro que menos ha crecido de la lista, indicando que el financiamiento a través de la emisión de acciones o el aporte de capital ha sido la fuente de recursos menos dinámica en el periodo 2022-2024. El mayor crecimiento ha provenido de la actividad operativa (Cuentas por Cobrar) y de pasivos (Cuentas por Pagar Comerciales).
C43: Planta y equipo | E43: =(M14-K14)/K14 -> 0.27777778
...

Sheet Parte 5
A1: =IF(Indicaciones!G18="","",SUM(A9:A16)) -> 0 | B1: Tasas de interés
B9: 1 | C9: 1 | D9: Calcule la TEA de la Alternativa A.
B11: 2 | C11: 1 | D11: Convierta la TET de la Alternativa B a TEA.
B13: 3 | C13: 1 | D13: Calcule el valor futuro de ambas alternativas a los 3 años
D14: Alternativa "A" | G14: y Alternativa "B"
B16: 4 | C16: 2 | D16: El Sr. Martínez desea saber cuánto debe depositar hoy para retirar S/ 70,000 en 5 años usando la mejor alternativa.
